[32m2025-08-30 21:32:12 +0000[0m - dagster - [34mDEBUG[0m - __ASSET_JOB - 6ccd95d7-e17d-44f1-b0fd-10ac4ebcbaf1 - 128993 - LOGS_CAPTURED - Started capturing logs in process (pid: 128993).
[32m2025-08-30 21:32:12 +0000[0m - dagster - [34mDEBUG[0m - __ASSET_JOB - 6ccd95d7-e17d-44f1-b0fd-10ac4ebcbaf1 - 128993 - leer_datos - STEP_START - Started execution of step "leer_datos".
[32m2025-08-30 21:32:12 +0000[0m - dagster - [34mERROR[0m - [31m__ASSET_JOB - 6ccd95d7-e17d-44f1-b0fd-10ac4ebcbaf1 - 128993 - leer_datos - STEP_FAILURE - Execution of step "leer_datos" failed.

dagster._core.errors.DagsterExecutionStepExecutionError: Error occurred while executing op "leer_datos"::

ValueError: Usecols do not match columns, columns expected but not found: ['country']

Stack Trace:
  File "/workspaces/Proyecto-dagster-covid/.venv/lib/python3.12/site-packages/dagster/_core/execution/plan/utils.py", line 57, in op_execution_error_boundary
    yield
  File "/workspaces/Proyecto-dagster-covid/.venv/lib/python3.12/site-packages/dagster/_utils/__init__.py", line 392, in iterate_with_context
    next_output = next(iterator)
                  ^^^^^^^^^^^^^^
  File "/workspaces/Proyecto-dagster-covid/.venv/lib/python3.12/site-packages/dagster/_core/execution/plan/compute_generator.py", line 137, in _coerce_op_compute_fn_to_iterator
    result = invoke_compute_fn(
             ^^^^^^^^^^^^^^^^^^
  File "/workspaces/Proyecto-dagster-covid/.venv/lib/python3.12/site-packages/dagster/_core/execution/plan/compute_generator.py", line 117, in invoke_compute_fn
    return fn(context, **args_to_pass) if context_arg_provided else fn(**args_to_pass)
                                                                    ^^^^^^^^^^^^^^^^^^
  File "/workspaces/Proyecto-dagster-covid/ProyectoFinal/src/ProyectoFinal/defs/assets.py", line 27, in leer_datos
    df = pd.read_csv(LOCAL_CSV, usecols=cols)
         ^^^^^^^^^^^^^^^^^^^^^^^^^^^^^^^^^^^^
  File "/workspaces/Proyecto-dagster-covid/.venv/lib/python3.12/site-packages/pandas/io/parsers/readers.py", line 1026, in read_csv
    return _read(filepath_or_buffer, kwds)
           ^^^^^^^^^^^^^^^^^^^^^^^^^^^^^^^
  File "/workspaces/Proyecto-dagster-covid/.venv/lib/python3.12/site-packages/pandas/io/parsers/readers.py", line 620, in _read
    parser = TextFileReader(filepath_or_buffer, **kwds)
             ^^^^^^^^^^^^^^^^^^^^^^^^^^^^^^^^^^^^^^^^^^
  File "/workspaces/Proyecto-dagster-covid/.venv/lib/python3.12/site-packages/pandas/io/parsers/readers.py", line 1620, in __init__
    self._engine = self._make_engine(f, self.engine)
                   ^^^^^^^^^^^^^^^^^^^^^^^^^^^^^^^^^
  File "/workspaces/Proyecto-dagster-covid/.venv/lib/python3.12/site-packages/pandas/io/parsers/readers.py", line 1898, in _make_engine
    return mapping[engine](f, **self.options)
           ^^^^^^^^^^^^^^^^^^^^^^^^^^^^^^^^^^
  File "/workspaces/Proyecto-dagster-covid/.venv/lib/python3.12/site-packages/pandas/io/parsers/c_parser_wrapper.py", line 140, in __init__
    self._validate_usecols_names(usecols, self.orig_names)
  File "/workspaces/Proyecto-dagster-covid/.venv/lib/python3.12/site-packages/pandas/io/parsers/base_parser.py", line 988, in _validate_usecols_names
    raise ValueError(
[0m
