[32m2025-08-30 20:57:02 +0000[0m - dagster - [34mDEBUG[0m - __ASSET_JOB - b4cae089-0cb5-48f5-bfdf-682845f76cbe - 75463 - LOGS_CAPTURED - Started capturing logs in process (pid: 75463).
[32m2025-08-30 20:57:02 +0000[0m - dagster - [34mDEBUG[0m - __ASSET_JOB - b4cae089-0cb5-48f5-bfdf-682845f76cbe - 75463 - covid_peru - STEP_START - Started execution of step "covid_peru".
[32m2025-08-30 20:57:02 +0000[0m - dagster - [34mDEBUG[0m - __ASSET_JOB - b4cae089-0cb5-48f5-bfdf-682845f76cbe - covid_peru - Loading file from: /workspaces/Proyecto-dagster-covid/ProyectoFinal/.tmp_dagster_home_q4dabyrq/storage/covid_raw using PickledObjectFilesystemIOManager...
[32m2025-08-30 20:57:02 +0000[0m - dagster - [34mDEBUG[0m - __ASSET_JOB - b4cae089-0cb5-48f5-bfdf-682845f76cbe - 75463 - covid_peru - LOADED_INPUT - Loaded input "covid_raw" using input manager "io_manager", from output "result" of step "covid_raw"
[32m2025-08-30 20:57:02 +0000[0m - dagster - [34mDEBUG[0m - __ASSET_JOB - b4cae089-0cb5-48f5-bfdf-682845f76cbe - 75463 - covid_peru - STEP_INPUT - Got input "covid_raw" of type "DataFrame". (Type check passed).
[32m2025-08-30 20:57:02 +0000[0m - dagster - [34mERROR[0m - [31m__ASSET_JOB - b4cae089-0cb5-48f5-bfdf-682845f76cbe - 75463 - covid_peru - STEP_FAILURE - Execution of step "covid_peru" failed.

dagster._core.errors.DagsterExecutionStepExecutionError: Error occurred while executing op "covid_peru"::

KeyError: 'location'

Stack Trace:
  File "/workspaces/Proyecto-dagster-covid/.venv/lib/python3.12/site-packages/dagster/_core/execution/plan/utils.py", line 57, in op_execution_error_boundary
    yield
  File "/workspaces/Proyecto-dagster-covid/.venv/lib/python3.12/site-packages/dagster/_utils/__init__.py", line 392, in iterate_with_context
    next_output = next(iterator)
                  ^^^^^^^^^^^^^^
  File "/workspaces/Proyecto-dagster-covid/.venv/lib/python3.12/site-packages/dagster/_core/execution/plan/compute_generator.py", line 137, in _coerce_op_compute_fn_to_iterator
    result = invoke_compute_fn(
             ^^^^^^^^^^^^^^^^^^
  File "/workspaces/Proyecto-dagster-covid/.venv/lib/python3.12/site-packages/dagster/_core/execution/plan/compute_generator.py", line 117, in invoke_compute_fn
    return fn(context, **args_to_pass) if context_arg_provided else fn(**args_to_pass)
                                                                    ^^^^^^^^^^^^^^^^^^
  File "/workspaces/Proyecto-dagster-covid/ProyectoFinal/src/ProyectoFinal/defs/assets.py", line 20, in covid_peru
    return covid_raw[covid_raw["location"] == "Peru"]
                     ~~~~~~~~~^^^^^^^^^^^^
  File "/workspaces/Proyecto-dagster-covid/.venv/lib/python3.12/site-packages/pandas/core/frame.py", line 4107, in __getitem__
    indexer = self.columns.get_loc(key)
              ^^^^^^^^^^^^^^^^^^^^^^^^^
  File "/workspaces/Proyecto-dagster-covid/.venv/lib/python3.12/site-packages/pandas/core/indexes/base.py", line 3819, in get_loc
    raise KeyError(key) from err

The above exception was caused by the following exception:
KeyError: 'location'

Stack Trace:
  File "/workspaces/Proyecto-dagster-covid/.venv/lib/python3.12/site-packages/pandas/core/indexes/base.py", line 3812, in get_loc
    return self._engine.get_loc(casted_key)
           ^^^^^^^^^^^^^^^^^^^^^^^^^^^^^^^^
  File "pandas/_libs/index.pyx", line 167, in pandas._libs.index.IndexEngine.get_loc
  File "pandas/_libs/index.pyx", line 196, in pandas._libs.index.IndexEngine.get_loc
  File "pandas/_libs/hashtable_class_helper.pxi", line 7088, in pandas._libs.hashtable.PyObjectHashTable.get_item
  File "pandas/_libs/hashtable_class_helper.pxi", line 7096, in pandas._libs.hashtable.PyObjectHashTable.get_item
[0m
