[32m2025-08-30 21:06:05 +0000[0m - dagster - [34mDEBUG[0m - __ASSET_JOB - e96931cd-a592-4dac-9db3-326c8409f385 - 88168 - LOGS_CAPTURED - Started capturing logs in process (pid: 88168).
[32m2025-08-30 21:06:05 +0000[0m - dagster - [34mDEBUG[0m - __ASSET_JOB - e96931cd-a592-4dac-9db3-326c8409f385 - 88168 - leer_datos - STEP_START - Started execution of step "leer_datos".
[32m2025-08-30 21:06:05 +0000[0m - dagster - [34mERROR[0m - [31m__ASSET_JOB - e96931cd-a592-4dac-9db3-326c8409f385 - 88168 - leer_datos - STEP_FAILURE - Execution of step "leer_datos" failed.

dagster._core.errors.DagsterExecutionStepExecutionError: Error occurred while executing op "leer_datos"::

requests.exceptions.ConnectionError: HTTPSConnectionPool(host='covid.ourworldindata.org', port=443): Max retries exceeded with url: /data/owid-covid-data.csv (Caused by NameResolutionError("<urllib3.connection.HTTPSConnection object at 0x7fc8bb8a3dd0>: Failed to resolve 'covid.ourworldindata.org' ([Errno -2] Name or service not known)"))

Stack Trace:
  File "/workspaces/Proyecto-dagster-covid/.venv/lib/python3.12/site-packages/dagster/_core/execution/plan/utils.py", line 57, in op_execution_error_boundary
    yield
  File "/workspaces/Proyecto-dagster-covid/.venv/lib/python3.12/site-packages/dagster/_utils/__init__.py", line 392, in iterate_with_context
    next_output = next(iterator)
                  ^^^^^^^^^^^^^^
  File "/workspaces/Proyecto-dagster-covid/.venv/lib/python3.12/site-packages/dagster/_core/execution/plan/compute_generator.py", line 137, in _coerce_op_compute_fn_to_iterator
    result = invoke_compute_fn(
             ^^^^^^^^^^^^^^^^^^
  File "/workspaces/Proyecto-dagster-covid/.venv/lib/python3.12/site-packages/dagster/_core/execution/plan/compute_generator.py", line 117, in invoke_compute_fn
    return fn(context, **args_to_pass) if context_arg_provided else fn(**args_to_pass)
                                                                    ^^^^^^^^^^^^^^^^^^
  File "/workspaces/Proyecto-dagster-covid/ProyectoFinal/src/ProyectoFinal/defs/assets.py", line 16, in leer_datos
    r = requests.get(DATA_URL)
        ^^^^^^^^^^^^^^^^^^^^^^
  File "/workspaces/Proyecto-dagster-covid/.venv/lib/python3.12/site-packages/requests/api.py", line 73, in get
    return request("get", url, params=params, **kwargs)
           ^^^^^^^^^^^^^^^^^^^^^^^^^^^^^^^^^^^^^^^^^^^^
  File "/workspaces/Proyecto-dagster-covid/.venv/lib/python3.12/site-packages/requests/api.py", line 59, in request
    return session.request(method=method, url=url, **kwargs)
           ^^^^^^^^^^^^^^^^^^^^^^^^^^^^^^^^^^^^^^^^^^^^^^^^^
  File "/workspaces/Proyecto-dagster-covid/.venv/lib/python3.12/site-packages/requests/sessions.py", line 589, in request
    resp = self.send(prep, **send_kwargs)
           ^^^^^^^^^^^^^^^^^^^^^^^^^^^^^^
  File "/workspaces/Proyecto-dagster-covid/.venv/lib/python3.12/site-packages/requests/sessions.py", line 703, in send
    r = adapter.send(request, **kwargs)
        ^^^^^^^^^^^^^^^^^^^^^^^^^^^^^^^
  File "/workspaces/Proyecto-dagster-covid/.venv/lib/python3.12/site-packages/requests/adapters.py", line 677, in send
    raise ConnectionError(e, request=request)

The above exception occurred during handling of the following exception:
urllib3.exceptions.MaxRetryError: HTTPSConnectionPool(host='covid.ourworldindata.org', port=443): Max retries exceeded with url: /data/owid-covid-data.csv (Caused by NameResolutionError("<urllib3.connection.HTTPSConnection object at 0x7fc8bb8a3dd0>: Failed to resolve 'covid.ourworldindata.org' ([Errno -2] Name or service not known)"))

Stack Trace:
  File "/workspaces/Proyecto-dagster-covid/.venv/lib/python3.12/site-packages/requests/adapters.py", line 644, in send
    resp = conn.urlopen(
           ^^^^^^^^^^^^^
  File "/workspaces/Proyecto-dagster-covid/.venv/lib/python3.12/site-packages/urllib3/connectionpool.py", line 841, in urlopen
    retries = retries.increment(
              ^^^^^^^^^^^^^^^^^^
  File "/workspaces/Proyecto-dagster-covid/.venv/lib/python3.12/site-packages/urllib3/util/retry.py", line 519, in increment
    raise MaxRetryError(_pool, url, reason) from reason  # type: ignore[arg-type]
    ^^^^^^^^^^^^^^^^^^^^^^^^^^^^^^^^^^^^^^^^^^^^^^^^^^^

The above exception was caused by the following exception:
urllib3.exceptions.NameResolutionError: <urllib3.connection.HTTPSConnection object at 0x7fc8bb8a3dd0>: Failed to resolve 'covid.ourworldindata.org' ([Errno -2] Name or service not known)

Stack Trace:
  File "/workspaces/Proyecto-dagster-covid/.venv/lib/python3.12/site-packages/urllib3/connectionpool.py", line 787, in urlopen
    response = self._make_request(
               ^^^^^^^^^^^^^^^^^^^
  File "/workspaces/Proyecto-dagster-covid/.venv/lib/python3.12/site-packages/urllib3/connectionpool.py", line 488, in _make_request
    raise new_e
  File "/workspaces/Proyecto-dagster-covid/.venv/lib/python3.12/site-packages/urllib3/connectionpool.py", line 464, in _make_request
    self._validate_conn(conn)
  File "/workspaces/Proyecto-dagster-covid/.venv/lib/python3.12/site-packages/urllib3/connectionpool.py", line 1093, in _validate_conn
    conn.connect()
  File "/workspaces/Proyecto-dagster-covid/.venv/lib/python3.12/site-packages/urllib3/connection.py", line 753, in connect
    self.sock = sock = self._new_conn()
                       ^^^^^^^^^^^^^^^^
  File "/workspaces/Proyecto-dagster-covid/.venv/lib/python3.12/site-packages/urllib3/connection.py", line 205, in _new_conn
    raise NameResolutionError(self.host, self, e) from e

The above exception was caused by the following exception:
socket.gaierror: [Errno -2] Name or service not known

Stack Trace:
  File "/workspaces/Proyecto-dagster-covid/.venv/lib/python3.12/site-packages/urllib3/connection.py", line 198, in _new_conn
    sock = connection.create_connection(
           ^^^^^^^^^^^^^^^^^^^^^^^^^^^^^
  File "/workspaces/Proyecto-dagster-covid/.venv/lib/python3.12/site-packages/urllib3/util/connection.py", line 60, in create_connection
    for res in socket.getaddrinfo(host, port, family, socket.SOCK_STREAM):
               ^^^^^^^^^^^^^^^^^^^^^^^^^^^^^^^^^^^^^^^^^^^^^^^^^^^^^^^^^^
  File "/home/codespace/.python/current/lib/python3.12/socket.py", line 963, in getaddrinfo
    for res in _socket.getaddrinfo(host, port, family, type, proto, flags):
               ^^^^^^^^^^^^^^^^^^^^^^^^^^^^^^^^^^^^^^^^^^^^^^^^^^^^^^^^^^^
[0m
