[32m2025-08-30 21:19:39 +0000[0m - dagster - [34mDEBUG[0m - __ASSET_JOB - 1f53d40f-0c6e-4754-8a37-5c5fd1389fb4 - 109892 - LOGS_CAPTURED - Started capturing logs in process (pid: 109892).
[32m2025-08-30 21:19:39 +0000[0m - dagster - [34mDEBUG[0m - __ASSET_JOB - 1f53d40f-0c6e-4754-8a37-5c5fd1389fb4 - 109892 - leer_datos - STEP_START - Started execution of step "leer_datos".
[32m2025-08-30 21:19:39 +0000[0m - dagster - [34mERROR[0m - [31m__ASSET_JOB - 1f53d40f-0c6e-4754-8a37-5c5fd1389fb4 - 109892 - leer_datos - STEP_FAILURE - Execution of step "leer_datos" failed.

dagster._core.errors.DagsterExecutionStepExecutionError: Error occurred while executing op "leer_datos"::

FileNotFoundError: Archivo no encontrado: /workspaces/Proyecto-dagster-covid/ProyectoFinal/covid-data.csv
Verifica que 'covid-data.csv' est√© en la ra√≠z del proyecto.

Stack Trace:
  File "/workspaces/Proyecto-dagster-covid/.venv/lib/python3.12/site-packages/dagster/_core/execution/plan/utils.py", line 57, in op_execution_error_boundary
    yield
  File "/workspaces/Proyecto-dagster-covid/.venv/lib/python3.12/site-packages/dagster/_utils/__init__.py", line 392, in iterate_with_context
    next_output = next(iterator)
                  ^^^^^^^^^^^^^^
  File "/workspaces/Proyecto-dagster-covid/.venv/lib/python3.12/site-packages/dagster/_core/execution/plan/compute_generator.py", line 137, in _coerce_op_compute_fn_to_iterator
    result = invoke_compute_fn(
             ^^^^^^^^^^^^^^^^^^
  File "/workspaces/Proyecto-dagster-covid/.venv/lib/python3.12/site-packages/dagster/_core/execution/plan/compute_generator.py", line 117, in invoke_compute_fn
    return fn(context, **args_to_pass) if context_arg_provided else fn(**args_to_pass)
                                                                    ^^^^^^^^^^^^^^^^^^
  File "/workspaces/Proyecto-dagster-covid/ProyectoFinal/src/ProyectoFinal/defs/assets.py", line 31, in leer_datos
    raise FileNotFoundError(
[0m
