[32m2025-08-30 21:09:52 +0000[0m - dagster - [34mDEBUG[0m - __ASSET_JOB - 4e1ba0b0-85c6-46d4-9cb0-d2a58608c654 - 94285 - LOGS_CAPTURED - Started capturing logs in process (pid: 94285).
[32m2025-08-30 21:09:52 +0000[0m - dagster - [34mDEBUG[0m - __ASSET_JOB - 4e1ba0b0-85c6-46d4-9cb0-d2a58608c654 - 94285 - leer_datos - STEP_START - Started execution of step "leer_datos".
[32m2025-08-30 21:09:52 +0000[0m - dagster - [34mERROR[0m - [31m__ASSET_JOB - 4e1ba0b0-85c6-46d4-9cb0-d2a58608c654 - 94285 - leer_datos - STEP_FAILURE - Execution of step "leer_datos" failed.

dagster._core.errors.DagsterExecutionStepExecutionError: Error occurred while executing op "leer_datos"::

NameError: name 'DATA_URL' is not defined

Stack Trace:
  File "/workspaces/Proyecto-dagster-covid/.venv/lib/python3.12/site-packages/dagster/_core/execution/plan/utils.py", line 57, in op_execution_error_boundary
    yield
  File "/workspaces/Proyecto-dagster-covid/.venv/lib/python3.12/site-packages/dagster/_utils/__init__.py", line 392, in iterate_with_context
    next_output = next(iterator)
                  ^^^^^^^^^^^^^^
  File "/workspaces/Proyecto-dagster-covid/.venv/lib/python3.12/site-packages/dagster/_core/execution/plan/compute_generator.py", line 137, in _coerce_op_compute_fn_to_iterator
    result = invoke_compute_fn(
             ^^^^^^^^^^^^^^^^^^
  File "/workspaces/Proyecto-dagster-covid/.venv/lib/python3.12/site-packages/dagster/_core/execution/plan/compute_generator.py", line 117, in invoke_compute_fn
    return fn(context, **args_to_pass) if context_arg_provided else fn(**args_to_pass)
                                                                    ^^^^^^^^^^^^^^^^^^
  File "/workspaces/Proyecto-dagster-covid/ProyectoFinal/src/ProyectoFinal/defs/assets.py", line 23, in leer_datos
    r = requests.get(DATA_URL)
                     ^^^^^^^^
[0m
